Workbook

Sheet African teams games since 2023
A1: Match ID | B1: year | C1: date | D1: team_id | E1: team | F1: opponent_id | G1: opponent | H1: opponent continent | I1: goals_scored | J1: goals_conceded | K1: tournament | L1: result
A2: MID 4986 | B2: =YEAR(C2) -> 1960 | C2: 21916 | D2: 188 | E2: Morocco | F2: 322 | G2: Yugoslavia | H2: Europe | I2: 0 | J2: 5 | K2: Friendly | L2: loss
A3: MID 4987 | B3: =YEAR(C3) -> 1960 | C3: 21918 | D3: 292 | E3: Tunisia | F3: 322 | G3: Yugoslavia | H3: Europe | I3: 1 | J3: 5 | K3: Friendly | L3: loss
A4: MID 4989 | B4: =YEAR(C4) -> 1960 | C4: 21923 | D4: 84 | E4: Egypt | F4: 322 | G4: Yugoslavia | H4: Europe | I4: 0 | J4: 1 | K4: Friendly | L4: loss
A5: MID 4990 | B5: =YEAR(C5) -> 1960 | C5: 21942 | D5: 122 | E5: Guinea-Bissau | F5: 106 | G5: Gambia | H5: Africa | I5: 3 | J5: 2 | K5: Friendly | L5: win
A6: MID 4991 | B6: =YEAR(C6) -> 1960 | C6: 21946 | D6: 122 | E6: Guinea-Bissau | F6: 259 | G6: Sierra Leone | H6: Africa | I6: 3 | J6: 4 | K6: Friendly | L6: loss
A7: MID 4992 | B7: =YEAR(C7) -> 1960 | C7: 21953 | D7: 110 | E7: Ghana | F7: 259 | G7: Sierra Leone | H7: Africa | I7: 6 | J7: 2 | K7: Friendly | L7: win
A8: MID 5022 | B8: =YEAR(C8) -> 1960 | C8: 22020 | D8: 140 | E8: Ivory Coast | F8: 31 | G8: Benin | H8: Africa | I8: 3 | J8: 2 | K8: African Friendship Games | L8: win
A9: MID 5023 | B9: =YEAR(C9) -> 1960 | C9: 22020 | D9: 44 | E9: Burkina Faso | F9: 103 | G9: Gabon | H9: Africa | I9: 5 | J9: 4 | K9: African Friendship Games | L9: win
A10: MID 5024 | B10: =YEAR(C10) -> 1960 | C10: 22020 | D10: 64 | E10: Congo | F10: 229 | G10: Réunion | H10: Africa | I10: 4 | J10: 1 | K10: African Friendship Games | L10: win
A11: MID 5025 | B11: =YEAR(C11) -> 1960 | C11: 22020 | D11: 47 | E11: Cameroon | F11: 78 | G11: Djibouti | H11: Africa | I11: 9 | J11: 2 | K11: African Friendship Games | L11: win
A12: MID 5026 | B12: =YEAR(C12) -> 1960 | C12: 22020 | D12: 170 | E12: Mali | F12: 54 | G12: Central African Republic | H12: Africa | I12: 4 | J12: 3 | K12: African Friendship Games | L12: win
A13: MID 5027 | B13: =YEAR(C13) -> 1960 | C13: 22021 | D13: 64 | E13: Congo | F13: 140 | G13: Ivory Coast | H13: Africa | I13: 3 | J13: 2 | K13: African Friendship Games | L13: win
... A21396: MID 49215 | B21396: =YEAR(C21396) -> 2026 | C21396: 46112 | D21396: 165 | E21396: Madagascar | F21396: 89 | G21396: Equatorial Guinea | H21396: Africa | I21396: 1 | J21396: 1 | K21396: Friendly | L21396: draw

Sheet Top african Scorers
A1: rank | B1: player | C1: player pic | D1: country | E1: country url | F1: goals
A2: 1 | B2: Asamoah Gyan | C2: https://onedrive.live.com/?viewid=b8bca9dd%2D9c77%2D4928%2D95d3%2Daa901ab4ef0e&id=%2Fpersonal%2F1c26c7920172286d%2FDocuments%2FDocuments%2Fimages%2FAsamoah%5FGyan%5F%282014%29%2Ejpg&parent=%2Fpersonal%2F1c26c7920172286d%2FDocuments%2FDocuments%2Fimages.png | D2: Ghana | E2: https://www.countryflags.com/flag-of-ghana/.png | F2: 6
A3: 2 | B3: Roger Milla | C3: https://onedrive.live.com/?id=%2Fpersonal%2F1c26c7920172286d%2FDocuments%2FDocuments%2Fimages%2Froger%20milla%2Ejfif&parent=%2Fpersonal%2F1c26c7920172286d%2FDocuments%2FDocuments%2Fimages&viewid=b8bca9dd%2D9c77%2D4928%2D95d3%2Daa901ab4ef0e.png | D3: Cameroon | E3: ="https://www.countryflags.com/flag-of-"&LOWER(D3)&"/.png" -> https://www.countryflags.com/flag-of-cameroon/.png | F3: 5
A4: 3 | B4: Ahmed Musa | C4: https://onedrive.live.com/?viewid=b8bca9dd%2D9c77%2D4928%2D95d3%2Daa901ab4ef0e&id=%2Fpersonal%2F1c26c7920172286d%2FDocuments%2FDocuments%2Fimages%2FAhmed%5FMusa%5F20180625%2Ejpg&parent=%2Fpersonal%2F1c26c7920172286d%2FDocuments%2FDocuments%2Fimages.png | D4: Nigeria | E4: ="https://www.countryflags.com/flag-of-"&LOWER(D4)&"/.png" -> https://www.countryflags.com/flag-of-nigeria/.png | F4: 4
A5: 4 | B5: Samuel Etoo | C5: https://onedrive.live.com/?id=%2Fpersonal%2F1c26c7920172286d%2FDocuments%2FDocuments%2Fimages%2Fsamuel%2Deto%27o%2Dcameroon%2D550nw%2D1182382gi%2Ejpg&parent=%2Fpersonal%2F1c26c7920172286d%2FDocuments%2FDocuments%2Fimages&viewid=b8bca9dd%2D9c77%2D4928%2D95d3%2Daa901ab4ef0e.png | D5: Cameroon | E5: ="https://www.countryflags.com/flag-of-"&LOWER(D5)&"/.png" -> https://www.countryflags.com/flag-of-cameroon/.png | F5: 3
A6: 4 | B6: Andre Ayew | C6: https://onedrive.live.com/?id=%2Fpersonal%2F1c26c7920172286d%2FDocuments%2FDocuments%2Fimages%2Fayew%2Ejfif&parent=%2Fpersonal%2F1c26c7920172286d%2FDocuments%2FDocuments%2Fimages&viewid=b8bca9dd%2D9c77%2D4928%2D95d3%2Daa901ab4ef0e.png | D6: Ghana | E6: ="https://www.countryflags.com/flag-of-"&LOWER(D6)&"/.png" -> https://www.countryflags.com/flag-of-ghana/.png | F6: 3

Sheet World Cup Games - CAF teams
A1: Match ID | B1: date | C1: team_id | D1: team | E1: opponent_id | F1: opponent | G1: opponent continent | H1: goals_scored | I1: goals_conceded | J1: tournament | K1: results | L1: stage
A2: MID 1876 | B2: 12566 | C2: 84 | D2: Egypt | E2: 129 | F2: Hungary | G2: Europe | H2: 2 | I2: 4 | J2: FIFA World Cup | K2: loss | L2: =_xlfn.XLOOKUP(A2,[1]!World_Cup_Games[Match ID],[1]!World_Cup_Games[Stage],,0) -> Preliminary round
A3: MID 8066 | B3: 25725 | C3: 188 | D3: Morocco | E3: 219 | F3: Peru | G3: South America | H3: 0 | I3: 3 | J3: FIFA World Cup | K3: loss | L3: =_xlfn.XLOOKUP(A3,[1]!World_Cup_Games[Match ID],[1]!World_Cup_Games[Stage],,0) -> Group Stages
A4: MID 9768 | B4: 27194 | C4: 82 | D4: DR Congo | E4: 252 | F4: Scotland | G4: Europe | H4: 0 | I4: 2 | J4: FIFA World Cup | K4: loss | L4: =_xlfn.XLOOKUP(A4,[1]!World_Cup_Games[Match ID],[1]!World_Cup_Games[Stage],,0) -> Group Stages
A5: MID 9782 | B5: 27202 | C5: 82 | D5: DR Congo | E5: 39 | F5: Brazil | G5: South America | H5: 0 | I5: 3 | J5: FIFA World Cup | K5: loss | L5: =_xlfn.XLOOKUP(A5,[1]!World_Cup_Games[Match ID],[1]!World_Cup_Games[Stage],,0) -> Group Stages
A6: MID 13320 | B6: 30123 | C6: 6 | D6: Algeria | E6: 19 | F6: Austria | G6: Europe | H6: 0 | I6: 2 | J6: FIFA World Cup | K6: loss | L6: =_xlfn.XLOOKUP(A6,[1]!World_Cup_Games[Match ID],[1]!World_Cup_Games[Stage],,0) -> Group Stages
A7: MID 13330 | B7: 30126 | C7: 6 | D7: Algeria | E7: 60 | F7: Chile | G7: South America | H7: 3 | I7: 2 | J7: FIFA World Cup | K7: win | L7: =_xlfn.XLOOKUP(A7,[1]!World_Cup_Games[Match ID],[1]!World_Cup_Games[Stage],,0) -> Group Stages
A8: MID 15320 | B8: 31565 | C8: 188 | D8: Morocco | E8: 221 | F8: Poland | G8: Europe | H8: 0 | I8: 0 | J8: FIFA World Cup | K8: draw | L8: =_xlfn.XLOOKUP(A8,[1]!World_Cup_Games[Match ID],[1]!World_Cup_Games[Stage],,0) -> Group Stages
A9: MID 15324 | B9: 31566 | C9: 6 | D9: Algeria | E9: 204 | F9: Northern Ireland | G9: Europe | H9: 1 | I9: 1 | J9: FIFA World Cup | K9: draw | L9: =_xlfn.XLOOKUP(A9,[1]!World_Cup_Games[Match ID],[1]!World_Cup_Games[Stage],,0) -> Group Stages
A10: MID 15354 | B10: 31575 | C10: 6 | D10: Algeria | E10: 272 | F10: Spain | G10: Europe | H10: 0 | I10: 3 | J10: FIFA World Cup | K10: loss | L10: =_xlfn.XLOOKUP(A10,[1]!World_Cup_Games[Match ID],[1]!World_Cup_Games[Stage],,0) -> Group Stages
A11: MID 15364 | B11: 31580 | C11: 188 | D11: Morocco | E11: 109 | F11: Germany | G11: Europe | H11: 0 | I11: 1 | J11: FIFA World Cup | K11: loss | L11: =_xlfn.XLOOKUP(A11,[1]!World_Cup_Games[Match ID],[1]!World_Cup_Games[Stage],,0) -> Round of 16
A12: MID 17336 | B12: 33038 | C12: 47 | D12: Cameroon | E12: 232 | F12: Romania | G12: Europe | H12: 2 | I12: 1 | J12: FIFA World Cup | K12: win | L12: =_xlfn.XLOOKUP(A12,[1]!World_Cup_Games[Match ID],[1]!World_Cup_Games[Stage],,0) -> Group Stages
A13: MID 17345 | B13: 33042 | C13: 47 | D13: Cameroon | E13: 233 | F13: Russia | G13: Europe | H13: 0 | I13: 4 | J13: FIFA World Cup | K13: loss | L13: =_xlfn.XLOOKUP(A13,[1]!World_Cup_Games[Match ID],[1]!World_Cup_Games[Stage],,0) -> Group Stages
... A163: MID 45748 | B163: 44912 | C163: 188 | D163: Morocco | E163: 69 | F163: Croatia | G163: Europe | H163: 1 | I163: 2 | J163: FIFA World Cup | K163: loss | L163: =_xlfn.XLOOKUP(A163,[1]!World_Cup_Games[Match ID],[1]!World_Cup_Games[Stage],,0) -> Third place playoff

Sheet fifa rankings CAF
A1: rank | B1: country_id | C1: country_full | D1: country_abrv | E1: confederation | F1: rank_date
A2: 32 | B2: =_xlfn.XLOOKUP(C2,country_id!$B$2:$B$326,country_id!$A$2:$A$326,,0) -> 323 | C2: Zambia | D2: ZAM | E2: CAF | F2: 33969
A3: 30 | B3: =_xlfn.XLOOKUP(C3,country_id!$B$2:$B$326,country_id!$A$2:$A$326,,0) -> 6 | C3: Algeria | D3: ALG | E3: CAF | F3: 33969
A4: 27 | B4: =_xlfn.XLOOKUP(C4,country_id!$B$2:$B$326,country_id!$A$2:$A$326,,0) -> 140 | C4: Ivory Coast | D4: CIV | E4: CAF | F4: 33969
A5: 22 | B5: =_xlfn.XLOOKUP(C5,country_id!$B$2:$B$326,country_id!$A$2:$A$326,,0) -> 47 | C5: Cameroon | D5: CMR | E5: CAF | F5: 33969
A6: 21 | B6: =_xlfn.XLOOKUP(C6,country_id!$B$2:$B$326,country_id!$A$2:$A$326,,0) -> 84 | C6: Egypt | D6: EGY | E6: CAF | F6: 33969
A7: 54 | B7: =_xlfn.XLOOKUP(C7,country_id!$B$2:$B$326,country_id!$A$2:$A$326,,0) -> 325 | C7: Zimbabwe | D7: ZIM | E7: CAF | F7: 33969
A8: 53 | B8: =_xlfn.XLOOKUP(C8,country_id!$B$2:$B$326,country_id!$A$2:$A$326,,0) -> 167 | C8: Malawi | D8: MWI | E8: CAF | F8: 33969
A9: 51 | B9: =_xlfn.XLOOKUP(C9,country_id!$B$2:$B$326,country_id!$A$2:$A$326,,0) -> 255 | C9: Senegal | D9: SEN | E9: CAF | F9: 33969
A10: 41 | B10: =_xlfn.XLOOKUP(C10,country_id!$B$2:$B$326,country_id!$A$2:$A$326,,0) -> 188 | C10: Morocco | D10: MAR | E10: CAF | F10: 33969
A11: 39 | B11: =_xlfn.XLOOKUP(C11,country_id!$B$2:$B$326,country_id!$A$2:$A$326,,0) -> 110 | C11: Ghana | D11: GHA | E11: CAF | F11: 33969
A12: 38 | B12: =_xlfn.XLOOKUP(C12,country_id!$B$2:$B$326,country_id!$A$2:$A$326,,0) -> 292 | C12: Tunisia | D12: TUN | E12: CAF | F12: 33969
A13: 55 | B13: =_xlfn.XLOOKUP(C13,country_id!$B$2:$B$326,country_id!$A$2:$A$326,,0) -> 103 | C13: Gabon | D13: GAB | E13: CAF | F13: 33969
... A17099: 186 | B17099: =_xlfn.XLOOKUP(C17099,country_id!$B$2:$B$326,country_id!$A$2:$A$326,,0) -> 247 | C17099: São Tomé and Príncipe | D17099: STP | E17099: CAF | F17099: 45225
B17100: =_xlfn.XLOOKUP(C17100,country_id!$B$2:$B$326,country_id!$A$2:$A$326,,0) -> 90 | C17100: Eritrea | D17100: ERI | E17100: CAF | F17100: 45225
A17101: 196 | B17101: =_xlfn.XLOOKUP(C17101,country_id!$B$2:$B$326,country_id!$A$2:$A$326,,0) -> 266 | C17101: Somalia | D17101: SOM | E17101: CAF | F17101: 45225
A17102: 195 | B17102: =_xlfn.XLOOKUP(C17102,country_id!$B$2:$B$326,country_id!$A$2:$A$326,,0) -> 257 | C17102: Seychelles | D17102: SEY | E17102: CAF | F17102: 45225
A17103: 189 | B17103: =_xlfn.XLOOKUP(C17103,country_id!$B$2:$B$326,country_id!$A$2:$A$326,,0) -> 78 | C17103: Djibouti | D17103: DJI | E17103: CAF | F17103: 45225
A17104: 129 | B17104: =_xlfn.XLOOKUP(C17104,country_id!$B$2:$B$326,country_id!$A$2:$A$326,,0) -> 197 | C17104: Niger | D17104: NIG | E17104: CAF | F17104: 45225
A17105: 128 | B17105: =_xlfn.XLOOKUP(C17105,country_id!$B$2:$B$326,country_id!$A$2:$A$326,,0) -> 63 | C17105: Comoros | D17105: COM | E17105: CAF | F17105: 45225
A17106: 127 | B17106: =_xlfn.XLOOKUP(C17106,country_id!$B$2:$B$326,country_id!$A$2:$A$326,,0) -> 54 | C17106: Central African Republic | D17106: CTA | E17106: CAF | F17106: 45225
A17107: 126 | B17107: =_xlfn.XLOOKUP(C17107,country_id!$B$2:$B$326,country_id!$A$2:$A$326,,0) -> 159 | C17107: Libya | D17107: LBY | E17107: CAF | F17107: 45225
A17108: 125 | B17108: =_xlfn.XLOOKUP(C17108,country_id!$B$2:$B$326,country_id!$A$2:$A$326,,0) -> 325 | C17108: Zimbabwe | D17108: ZIM | E17108: CAF | F17108: 45225
A17109: 123 | B17109: =_xlfn.XLOOKUP(C17109,country_id!$B$2:$B$326,country_id!$A$2:$A$326,,0) -> 167 | C17109: Malawi | D17109: MWI | E17109: CAF | F17109: 45225
A17110: 122 | B17110: =_xlfn.XLOOKUP(C17110,country_id!$B$2:$B$326,country_id!$A$2:$A$326,,0) -> 259 | C17110: Sierra Leone | D17110: SLE | E17110: CAF | F17110: 45225
A17111: 121 | B17111: =_xlfn.XLOOKUP(C17111,country_id!$B$2:$B$326,country_id!$A$2:$A$326,,0) -> 284 | C17111: Tanzania | D17111: TAN | E17111: CAF | F17111: 45225
A17112: 119 | B17112: =_xlfn.XLOOKUP(C17112,country_id!$B$2:$B$326,country_id!$A$2:$A$326,,0) -> 289 | C17112: Togo | D17112: TOG | E17112: CAF | F17112: 45225
... A17143: 13 | B17143: =_xlfn.XLOOKUP(C17143,country_id!$B$2:$B$326,country_id!$A$2:$A$326,,0) -> 188 | C17143: Morocco | D17143: MAR | E17143: CAF | F17143: 45260
B17144: =_xlfn.XLOOKUP(C17144,country_id!$B$2:$B$326,country_id!$A$2:$A$326,,0) -> 90 | C17144: Eritrea | D17144: ERI | E17144: CAF | F17144: 45260
A17145: 46 | B17145: =_xlfn.XLOOKUP(C17145,country_id!$B$2:$B$326,country_id!$A$2:$A$326,,0) -> 47 | C17145: Cameroon | D17145: CMR | E17145: CAF | F17145: 45260
A17146: 42 | B17146: =_xlfn.XLOOKUP(C17146,country_id!$B$2:$B$326,country_id!$A$2:$A$326,,0) -> 198 | C17146: Nigeria | D17146: NGA | E17146: CAF | F17146: 45260
A17147: 33 | B17147: =_xlfn.XLOOKUP(C17147,country_id!$B$2:$B$326,country_id!$A$2:$A$326,,0) -> 84 | C17147: Egypt | D17147: EGY | E17147: CAF | F17147: 45260
A17148: 30 | B17148: =_xlfn.XLOOKUP(C17148,country_id!$B$2:$B$326,country_id!$A$2:$A$326,,0) -> 6 | C17148: Algeria | D17148: ALG | E17148: CAF | F17148: 45260
A17149: 28 | B17149: =_xlfn.XLOOKUP(C17149,country_id!$B$2:$B$326,country_id!$A$2:$A$326,,0) -> 292 | C17149: Tunisia | D17149: TUN | E17149: CAF | F17149: 45260
A17150: 103 | B17150: =_xlfn.XLOOKUP(C17150,country_id!$B$2:$B$326,country_id!$A$2:$A$326,,0) -> 122 | C17150: Guinea-Bissau | D17150: GNB | E17150: CAF | F17150: 45260
A17151: 105 | B17151: =_xlfn.XLOOKUP(C17151,country_id!$B$2:$B$326,country_id!$A$2:$A$326,,0) -> 177 | C17151: Mauritania | D17151: MTN | E17151: CAF | F17151: 45260
A17152: 177 | B17152: =_xlfn.XLOOKUP(C17152,country_id!$B$2:$B$326,country_id!$A$2:$A$326,,0) -> 178 | C17152: Mauritius | D17152: MRI | E17152: CAF | F17152: 45260
A17153: 166 | B17153: =_xlfn.XLOOKUP(C17153,country_id!$B$2:$B$326,country_id!$A$2:$A$326,,0) -> 271 | C17153: South Sudan | D17153: SSD | E17153: CAF | F17153: 45260
A17154: 199 | B17154: =_xlfn.XLOOKUP(C17154,country_id!$B$2:$B$326,country_id!$A$2:$A$326,,0) -> 257 | C17154: Seychelles | D17154: SEY | E17154: CAF | F17154: 45260
A17155: 198 | B17155: =_xlfn.XLOOKUP(C17155,country_id!$B$2:$B$326,country_id!$A$2:$A$326,,0) -> 266 | C17155: Somalia | D17155: SOM | E17155: CAF | F17155: 45260
...

Sheet country_id
A1: ID | B1: Teams | C1: Continent
A2: 1 | B2: Abkhazia | C2: Europe
A3: 2 | B3: Afghanistan | C3: Asia
A4: 3 | B4: Åland Islands | C4: Europe
A5: 4 | B5: Albania | C5: Europe
A6: 5 | B6: Alderney | C6: Europe
A7: 6 | B7: Algeria | C7: Africa
A8: 7 | B8: American Samoa | C8: Oceania
A9: 8 | B9: Andalusia | C9: Europe
A10: 9 | B10: Andorra | C10: Europe
A11: 10 | B11: Angola | C11: Africa
A12: 11 | B12: Anguilla | C12: North America
A13: 12 | B13: Antigua and Barbuda | C13: North America
... A326: 325 | B326: Zimbabwe | C326: Africa

Sheet current fifa rankings
A1: Group | B1: Country ID | C1: Country | D1: FIFA Ranking
A2: A | B2: 181 | C2: Mexico | D2: 15
A3: A | B3: 268 | C3: South Africa | D3: 60
A4: A | B4: 269 | C4: South Korea | D4: 25
A5: A | B5: 73 | C5: Czech Republic | D5: 41
A6: B | B6: 48 | C6: Canada | D6: 30
A7: B | B7: 37 | C7: Bosnia & Herzegovina | D7: 65
A8: B | B8: 225 | C8: Qatar | D8: 55
A9: B | B9: 277 | C9: Switzerland | D9: 19
A10: C | B10: 39 | C10: Brazil | D10: 6
A11: C | B11: 188 | C11: Morocco | D11: 8
A12: C | B12: 124 | C12: Haiti | D12: 82
A13: C | B13: 252 | C13: Scotland | D13: 43
... A49: L | B49: 214 | C49: Panama | D49: 33
